<?xml version="1.0"?>
<robot xmlns:xacro="http://www.ros.org/wiki/xacro">

    <xacro:include filename="inertial_macros.xacro"/>

    <material name="white">
        <color rgba="1 1 1 1"/>
    </material>

    <material name="orange">
        <color rgba="1 0.3 0.1 1"/>
    </material>

    <material name="blue">
        <color rgba="0.2 0.2 1 1"/>
    </material>

    <material name="black">
        <color rgba="0 0 0 1"/>
    </material>

    <!-- ___________________________________ Base _______________________________ -->
    
    <joint name="world_joint" type="fixed">
        <parent link="world" />
        <child link="base" />
        <origin xyz="0 0 0" />
    </joint>

    <link name="world">
    </link>

    <link name="base">
        <visual>
            <origin xyz="0 0 0.05"/>
            <geometry>
                <cylinder radius="0.1355" length="0.1"/>
            </geometry>
            <material name="blue"/>
        </visual>
        <collision>
            <origin xyz="0 0 0.05"/>
            <geometry>
                <cylinder radius="0.1355" length="0.1"/>
            </geometry>
        </collision>
        <xacro:inertial_cylinder mass="5" length="0.1" radius="0.1355">
            <origin xyz="0 0 0" rpy="0 0 0"/>
        </xacro:inertial_cylinder>
    </link>

    <!-- ___________________________________ Rotating Base _______________________________ -->
    
    <joint name="rot_base_joint" type="continuous">
    <parent link="base"/>
    <child link="rot_base"/>
    <axis xyz="0 0 1"/>
    <origin xyz="0 0 0.1" rpy="0 0 0"/>
    </joint>
    
    <link name="rot_base">
        <visual>
            <origin xyz="-0.1355 0 0.2"/>
            <geometry>
                <mesh filename="package://example_package/meshes/rot_base.stl" scale="0.001 0.001 0.001" />
            </geometry>
            <material name="blue"/>
        </visual>
        <collision>
            <origin xyz="-0.1355 0 0.2"/>
            <geometry>
                <mesh filename="package://example_package/meshes/rot_base.stl" scale="0.001 0.001 0.001" />
            </geometry>
        </collision>
        <xacro:inertial_cylinder mass="2.5" length="0.05" radius="0.1355">
            <origin xyz="0 0 0" rpy="0 0 0"/>
        </xacro:inertial_cylinder>
    </link>

</robot>